<?xml version="1.0"?>

<robot xmlns:xacro="http://ros.org/wiki/xacro" name="front_wheel">
  
  <xacro:macro name="front_wheel" params="wheel_prefix *joint_pose">
    <xacro:property name="mesh_scale" value="0.001 0.001 0.001"/>
    <link name="${wheel_prefix}_wheel">
      <inertial>
        <mass value="12.0" />
        <origin xyz="0 0 0" />
        <inertia ixx="0.377" ixy="0" ixz="0" iyy="0.377" iyz="0" izz="0.673" />
      </inertial>
      <visual>
        <origin xyz="0 0 0" rpy="0 0 0" />
        <geometry>
          <mesh filename="package://clearpath_platform_description/meshes/max/front_wheel.stl" scale="${mesh_scale}"/>
        </geometry>
      </visual>
      <collision>
        <origin xyz="0 0 0" rpy="${M_PI/2} 0 0" />
        <geometry>
          <cylinder length="${front_wheel_width}" radius="${wheel_radius}" />
        </geometry>
      </collision>
    </link>

    <!-- <gazebo reference="${wheel_prefix}_wheel">
      <mu1 value="1.0"/>
      <mu2 value="0.5"/>
      <kp value="100000000000000000000.0" />
      <kd value="1.0" />
      <fdir1 value="1 0 0"/>
    </gazebo> -->

    <joint name="${wheel_prefix}_wheel_joint" type="continuous">
      <parent link="base_link"/>
      <child link="${wheel_prefix}_wheel"/>
      <xacro:insert_block name="joint_pose"/>
      <axis xyz="0 1 0" rpy="0 0 0" />
    </joint>

  </xacro:macro>
</robot>
